<?xml version="1.0" ?>
<robot name="partnet_ef6d92c90aeabf5becae27d182a3e41c">
	<link name="base"/>
	<link name="link_0">
		<visual name="screen-13">
			<origin xyz="0.04312540076091809 0.18940399999999946 0.1858512224381934"/>
			<geometry>
				<mesh filename="textured_objs/original-3.obj"/>
			</geometry>
		</visual>
		<visual name="screen-13">
			<origin xyz="0.04312540076091809 0.18940399999999946 0.1858512224381934"/>
			<geometry>
				<mesh filename="textured_objs/new-2.obj"/>
			</geometry>
		</visual>
		<visual name="screen_frame-14">
			<origin xyz="0.04312540076091809 0.18940399999999946 0.1858512224381934"/>
			<geometry>
				<mesh filename="textured_objs/new-3.obj"/>
			</geometry>
		</visual>
		<visual name="camera-15">
			<origin xyz="0.04312540076091809 0.18940399999999946 0.1858512224381934"/>
			<geometry>
				<mesh filename="textured_objs/original-18.obj"/>
			</geometry>
		</visual>
		<visual name="camera-15">
			<origin xyz="0.04312540076091809 0.18940399999999946 0.1858512224381934"/>
			<geometry>
				<mesh filename="textured_objs/original-19.obj"/>
			</geometry>
		</visual>
		<collision>
			<origin xyz="0.04312540076091809 0.18940399999999946 0.1858512224381934"/>
			<geometry>
				<mesh filename="textured_objs/original-3.obj"/>
			</geometry>
		</collision>
		<collision>
			<origin xyz="0.04312540076091809 0.18940399999999946 0.1858512224381934"/>
			<geometry>
				<mesh filename="textured_objs/new-2.obj"/>
			</geometry>
		</collision>
		<collision>
			<origin xyz="0.04312540076091809 0.18940399999999946 0.1858512224381934"/>
			<geometry>
				<mesh filename="textured_objs/new-3.obj"/>
			</geometry>
		</collision>
		<collision>
			<origin xyz="0.04312540076091809 0.18940399999999946 0.1858512224381934"/>
			<geometry>
				<mesh filename="textured_objs/original-18.obj"/>
			</geometry>
		</collision>
		<collision>
			<origin xyz="0.04312540076091809 0.18940399999999946 0.1858512224381934"/>
			<geometry>
				<mesh filename="textured_objs/original-19.obj"/>
			</geometry>
		</collision>
	</link>
	<joint name="joint_0" type="revolute">
		<origin xyz="-0.04312540076091809 -0.18940399999999946 -0.1858512224381934"/>
		<axis xyz="-0.9659257431444874 0 0"/>
		<child link="link_0"/>
		<parent link="link_1"/>
		<limit lower="-1.834690109696439" upper="-0.0"/>
	</joint>
	<link name="link_1">
		<visual name="keyboard-11">
			<origin xyz="0 0 0"/>
			<geometry>
				<mesh filename="textured_objs/new-0.obj"/>
			</geometry>
		</visual>
		<visual name="base_frame-12">
			<origin xyz="0 0 0"/>
			<geometry>
				<mesh filename="textured_objs/new-1.obj"/>
			</geometry>
		</visual>
		<visual name="base_frame-12">
			<origin xyz="0 0 0"/>
			<geometry>
				<mesh filename="textured_objs/original-22.obj"/>
			</geometry>
		</visual>
		<collision>
			<origin xyz="0 0 0"/>
			<geometry>
				<mesh filename="textured_objs/new-0.obj"/>
			</geometry>
		</collision>
		<collision>
			<origin xyz="0 0 0"/>
			<geometry>
				<mesh filename="textured_objs/new-1.obj"/>
			</geometry>
		</collision>
		<collision>
			<origin xyz="0 0 0"/>
			<geometry>
				<mesh filename="textured_objs/original-22.obj"/>
			</geometry>
		</collision>
	</link>
	<joint name="joint_1" type="fixed">
		<origin rpy="1.570796326794897 0 -1.570796326794897" xyz="0 0 0"/>
		<child link="link_1"/>
		<parent link="base"/>
	</joint>
</robot>
