<?xml version="1.0" ?>
<robot name="partnet_185cf76909e948f0fa80fb391ee7ccee">
	<link name="base"/>
	<link name="link_0">
		<visual name="frame-15">
			<origin xyz="0 0 0"/>
			<geometry>
				<mesh filename="textured_objs/new-1.obj"/>
			</geometry>
		</visual>
		<visual name="frame-15">
			<origin xyz="0 0 0"/>
			<geometry>
				<mesh filename="textured_objs/new-0.obj"/>
			</geometry>
		</visual>
		<visual name="frame-15">
			<origin xyz="0 0 0"/>
			<geometry>
				<mesh filename="textured_objs/original-18.obj"/>
			</geometry>
		</visual>
		<collision>
			<origin xyz="0 0 0"/>
			<geometry>
				<mesh filename="textured_objs/new-1.obj"/>
			</geometry>
		</collision>
		<collision>
			<origin xyz="0 0 0"/>
			<geometry>
				<mesh filename="textured_objs/new-0.obj"/>
			</geometry>
		</collision>
		<collision>
			<origin xyz="0 0 0"/>
			<geometry>
				<mesh filename="textured_objs/original-18.obj"/>
			</geometry>
		</collision>
	</link>
	<joint name="joint_0" type="fixed">
		<origin rpy="1.570796326794897 0 -1.570796326794897" xyz="0 0 0"/>
		<child link="link_0"/>
		<parent link="base"/>
	</joint>
	<link name="link_1">
		<visual name="display_panel-11">
			<origin xyz="0.06294762892501815 0.1261545965752331 -0.6810209999999997"/>
			<geometry>
				<mesh filename="textured_objs/new-3.obj"/>
			</geometry>
		</visual>
		<visual name="shelf-16">
			<origin xyz="0.06294762892501815 0.1261545965752331 -0.6810209999999997"/>
			<geometry>
				<mesh filename="textured_objs/original-3.obj"/>
			</geometry>
		</visual>
		<visual name="shelf-17">
			<origin xyz="0.06294762892501815 0.1261545965752331 -0.6810209999999997"/>
			<geometry>
				<mesh filename="textured_objs/original-4.obj"/>
			</geometry>
		</visual>
		<visual name="handle-12">
			<origin xyz="0.06294762892501815 0.1261545965752331 -0.6810209999999997"/>
			<geometry>
				<mesh filename="textured_objs/new-2.obj"/>
			</geometry>
		</visual>
		<visual name="glass-13">
			<origin xyz="0.06294762892501815 0.1261545965752331 -0.6810209999999997"/>
			<geometry>
				<mesh filename="textured_objs/new-4.obj"/>
			</geometry>
		</visual>
		<visual name="door_frame-20">
			<origin xyz="0.06294762892501815 0.1261545965752331 -0.6810209999999997"/>
			<geometry>
				<mesh filename="textured_objs/new-5.obj"/>
			</geometry>
		</visual>
		<collision>
			<origin xyz="0.06294762892501815 0.1261545965752331 -0.6810209999999997"/>
			<geometry>
				<mesh filename="textured_objs/new-3.obj"/>
			</geometry>
		</collision>
		<collision>
			<origin xyz="0.06294762892501815 0.1261545965752331 -0.6810209999999997"/>
			<geometry>
				<mesh filename="textured_objs/original-3.obj"/>
			</geometry>
		</collision>
		<collision>
			<origin xyz="0.06294762892501815 0.1261545965752331 -0.6810209999999997"/>
			<geometry>
				<mesh filename="textured_objs/original-4-part-0.obj"/>
			</geometry>
		</collision>
		<collision>
			<origin xyz="0.06294762892501815 0.1261545965752331 -0.6810209999999997"/>
			<geometry>
				<mesh filename="textured_objs/original-4-part-1.obj"/>
			</geometry>
		</collision>
		<collision>
			<origin xyz="0.06294762892501815 0.1261545965752331 -0.6810209999999997"/>
			<geometry>
				<mesh filename="textured_objs/original-4-part-2.obj"/>
			</geometry>
		</collision>
		<collision>
			<origin xyz="0.06294762892501815 0.1261545965752331 -0.6810209999999997"/>
			<geometry>
				<mesh filename="textured_objs/new-2.obj"/>
			</geometry>
		</collision>
		<collision>
			<origin xyz="0.06294762892501815 0.1261545965752331 -0.6810209999999997"/>
			<geometry>
				<mesh filename="textured_objs/new-4.obj"/>
			</geometry>
		</collision>
		<collision>
			<origin xyz="0.06294762892501815 0.1261545965752331 -0.6810209999999997"/>
			<geometry>
				<mesh filename="textured_objs/new-5.obj"/>
			</geometry>
		</collision>
	</link>
	<joint name="joint_1" type="prismatic">
		<origin xyz="-0.06294762892501815 -0.1261545965752331 0.6810209999999997"/>
		<axis xyz="0 0 0.9999999999999999"/>
		<child link="link_1"/>
		<parent link="link_0"/>
		<limit lower="-0.5760000000000001" upper="0.1359999999999999"/>
	</joint>
</robot>
