<?xml version="1.0" ?>
<robot name="partnet_99d08b28aeaa7471b4c8f245ce40b797">
	<link name="base"/>
	<link name="link_0">
		<visual name="handle-1">
			<origin xyz="-0.0001996910963944797 -0.2816371476433068 0.05553202097207162"/>
			<geometry>
				<mesh filename="textured_objs/original-4.obj"/>
			</geometry>
		</visual>
		<collision>
			<origin xyz="-0.0001996910963944797 -0.2816371476433068 0.05553202097207162"/>
			<geometry>
				<mesh filename="textured_objs/original-4-part-0.obj"/>
			</geometry>
		</collision>
		<collision>
			<origin xyz="-0.0001996910963944797 -0.2816371476433068 0.05553202097207162"/>
			<geometry>
				<mesh filename="textured_objs/original-4-part-1.obj"/>
			</geometry>
		</collision>
		<collision>
			<origin xyz="-0.0001996910963944797 -0.2816371476433068 0.05553202097207162"/>
			<geometry>
				<mesh filename="textured_objs/original-4-part-2.obj"/>
			</geometry>
		</collision>
		<collision>
			<origin xyz="-0.0001996910963944797 -0.2816371476433068 0.05553202097207162"/>
			<geometry>
				<mesh filename="textured_objs/original-4-part-3.obj"/>
			</geometry>
		</collision>
		<collision>
			<origin xyz="-0.0001996910963944797 -0.2816371476433068 0.05553202097207162"/>
			<geometry>
				<mesh filename="textured_objs/original-4-part-4.obj"/>
			</geometry>
		</collision>
		<collision>
			<origin xyz="-0.0001996910963944797 -0.2816371476433068 0.05553202097207162"/>
			<geometry>
				<mesh filename="textured_objs/original-4-part-5.obj"/>
			</geometry>
		</collision>
		<collision>
			<origin xyz="-0.0001996910963944797 -0.2816371476433068 0.05553202097207162"/>
			<geometry>
				<mesh filename="textured_objs/original-4-part-6.obj"/>
			</geometry>
		</collision>
		<collision>
			<origin xyz="-0.0001996910963944797 -0.2816371476433068 0.05553202097207162"/>
			<geometry>
				<mesh filename="textured_objs/original-4-part-7.obj"/>
			</geometry>
		</collision>
	</link>
	<joint name="joint_0" type="fixed">
		<origin xyz="0.0001996910963944797 0.2816371476433068 -0.05553202097207162"/>
		<child link="link_0"/>
		<parent link="link_1"/>
	</joint>
	<link name="link_1">
		<visual name="base_body-2">
			<origin xyz="0 0 0"/>
			<geometry>
				<mesh filename="textured_objs/original-3.obj"/>
			</geometry>
		</visual>
		<visual name="base_body-2">
			<origin xyz="0 0 0"/>
			<geometry>
				<mesh filename="textured_objs/original-2.obj"/>
			</geometry>
		</visual>
		<visual name="base_body-2">
			<origin xyz="0 0 0"/>
			<geometry>
				<mesh filename="textured_objs/original-1.obj"/>
			</geometry>
		</visual>
		<collision>
			<origin xyz="0 0 0"/>
			<geometry>
				<mesh filename="textured_objs/original-3.obj"/>
			</geometry>
		</collision>
		<collision>
			<origin xyz="0 0 0"/>
			<geometry>
				<mesh filename="textured_objs/original-2.obj"/>
			</geometry>
		</collision>
		<collision>
			<origin xyz="0 0 0"/>
			<geometry>
				<mesh filename="textured_objs/original-1.obj"/>
			</geometry>
		</collision>
	</link>
	<joint name="joint_1" type="prismatic">
		<origin rpy="1.570796326794897 0 -1.570796326794897" xyz="0 0 0"/>
		<axis xyz="0 0 -1"/>
		<child link="link_1"/>
		<parent link="base"/>
		<limit lower="0" upper="0.3"/>
	</joint>
</robot>
