<?xml version="1.0" ?>
<robot name="partnet_3f7d636f676850442a60b2309aec10ad">
	<link name="base"/>
	<link name="link_0">
		<visual name="outside_frame-3">
			<origin xyz="0 0 0"/>
			<geometry>
				<mesh filename="textured_objs/original-2.obj"/>
			</geometry>
		</visual>
		<visual name="outside_frame-3">
			<origin xyz="0 0 0"/>
			<geometry>
				<mesh filename="textured_objs/original-3.obj"/>
			</geometry>
		</visual>
		<visual name="outside_frame-3">
			<origin xyz="0 0 0"/>
			<geometry>
				<mesh filename="textured_objs/new-1.obj"/>
			</geometry>
		</visual>
		<collision>
			<origin xyz="0 0 0"/>
			<geometry>
				<mesh filename="textured_objs/original-2.obj"/>
			</geometry>
		</collision>
		<collision>
			<origin xyz="0 0 0"/>
			<geometry>
				<mesh filename="textured_objs/original-3.obj"/>
			</geometry>
		</collision>
		<collision>
			<origin xyz="0 0 0"/>
			<geometry>
				<mesh filename="textured_objs/new-1.obj"/>
			</geometry>
		</collision>
	</link>
	<joint name="joint_0" type="fixed">
		<origin rpy="1.570796326794897 0 -1.570796326794897" xyz="0 0 0"/>
		<child link="link_0"/>
		<parent link="base"/>
	</joint>
	<link name="link_1">
		<visual name="surface_board-9">
			<origin xyz="0.3229034707136453 0 -0.04352036807686092"/>
			<geometry>
				<mesh filename="textured_objs/new-2.obj"/>
			</geometry>
		</visual>
		<collision>
			<origin xyz="0.3229034707136453 0 -0.04352036807686092"/>
			<geometry>
				<mesh filename="textured_objs/new-2.obj"/>
			</geometry>
		</collision>
	</link>
	<joint name="joint_1" type="revolute">
		<origin xyz="-0.3229034707136453 0 0.04352036807686092"/>
		<axis xyz="0 1 0"/>
		<child link="link_1"/>
		<parent link="link_0"/>
		<limit lower="-1.5707963267948966" upper="0.0"/>
	</joint>
	<!-- <link name="link_2">
		<visual name="surface_board-7">
			<origin xyz="-0.3038980982638896 0 -0.058809246495366126"/>
			<geometry>
				<mesh filename="textured_objs/new-0.obj"/>
			</geometry>
		</visual>
		<collision>
			<origin xyz="-0.3038980982638896 0 -0.058809246495366126"/>
			<geometry>
				<mesh filename="textured_objs/new-0.obj"/>
			</geometry>
		</collision>
	</link>
	<joint name="joint_2" type="fixed">
		<origin xyz="0.3038980982638896 0 0.058809246495366126"/>
		<axis xyz="0 -1 0"/>
		<child link="link_2"/>
		<parent link="link_0"/>
		<limit lower="-1.5707963267948966" upper="-0.0"/>
	</joint> -->
</robot>
