<?xml version="1.0" ?>
<robot name="partnet_302dce155e54539bf54e1b6f41fdd78a">
	<link name="base"/>
	<link name="link_0">
		<visual name="handle-1">
			<origin xyz="0 -0.387119372849025 -0.0016758908051998176"/>
			<geometry>
				<mesh filename="textured_objs/original-1.obj"/>
			</geometry>
		</visual>
		<collision>
			<origin xyz="0 -0.387119372849025 -0.0016758908051998176"/>
			<geometry>
				<mesh filename="textured_objs/original-1.obj"/>
			</geometry>
		</collision>
	</link>
	<joint name="joint_0" type="revolute">
		<origin xyz="0 0.387119372849025 0.0016758908051998176"/>
		<axis xyz="-1 0 0"/>
		<child link="link_0"/>
		<parent link="link_1"/>
		<limit lower="-1.2692034320502759" upper="1.2692034320502759"/>
	</joint>
	<link name="link_1">
		<visual name="base_body-2">
			<origin xyz="0 0 0"/>
			<geometry>
				<mesh filename="textured_objs/original-2.obj"/>
			</geometry>
		</visual>
		<collision>
			<origin xyz="0 0 0"/>
			<geometry>
				<mesh filename="textured_objs/original-2.obj"/>
			</geometry>
		</collision>
	</link>
	<joint name="joint_1" type="fixed">
		<origin rpy="1.570796326794897 0 -1.570796326794897" xyz="0 0 0"/>
		<child link="link_1"/>
		<parent link="base"/>
	</joint>
</robot>
