<?xml version="1.0" ?>
<robot name="partnet_a95828fa4607295674c8eb7e4d6198a5">
	<link name="base"/>
	<link name="link_0">
		<visual name="board-51">
			<origin xyz="0 0 0"/>
			<geometry>
				<mesh filename="textured_objs/original-3.obj"/>
			</geometry>
		</visual>
		<visual name="shelf-41">
			<origin xyz="0 0 0"/>
			<geometry>
				<mesh filename="textured_objs/original-12.obj"/>
			</geometry>
		</visual>
		<visual name="shelf-41">
			<origin xyz="0 0 0"/>
			<geometry>
				<mesh filename="textured_objs/original-13.obj"/>
			</geometry>
		</visual>
		<visual name="shelf-41">
			<origin xyz="0 0 0"/>
			<geometry>
				<mesh filename="textured_objs/original-14.obj"/>
			</geometry>
		</visual>
		<visual name="vertical_side_panel-42">
			<origin xyz="0 0 0"/>
			<geometry>
				<mesh filename="textured_objs/original-27.obj"/>
			</geometry>
		</visual>
		<visual name="vertical_side_panel-43">
			<origin xyz="0 0 0"/>
			<geometry>
				<mesh filename="textured_objs/original-20.obj"/>
			</geometry>
		</visual>
		<visual name="leg-44">
			<origin xyz="0 0 0"/>
			<geometry>
				<mesh filename="textured_objs/original-19.obj"/>
			</geometry>
		</visual>
		<visual name="leg-45">
			<origin xyz="0 0 0"/>
			<geometry>
				<mesh filename="textured_objs/original-28.obj"/>
			</geometry>
		</visual>
		<visual name="leg-46">
			<origin xyz="0 0 0"/>
			<geometry>
				<mesh filename="textured_objs/original-21.obj"/>
			</geometry>
		</visual>
		<visual name="leg-47">
			<origin xyz="0 0 0"/>
			<geometry>
				<mesh filename="textured_objs/original-26.obj"/>
			</geometry>
		</visual>
		<visual name="other_leaf-65">
			<origin xyz="0 0 0"/>
			<geometry>
				<mesh filename="textured_objs/original-2.obj"/>
			</geometry>
		</visual>
		<collision>
			<origin xyz="0 0 0"/>
			<geometry>
				<mesh filename="textured_objs/original-3.obj"/>
			</geometry>
		</collision>
		<collision>
			<origin xyz="0 0 0"/>
			<geometry>
				<mesh filename="textured_objs/original-12.obj"/>
			</geometry>
		</collision>
		<collision>
			<origin xyz="0 0 0"/>
			<geometry>
				<mesh filename="textured_objs/original-13.obj"/>
			</geometry>
		</collision>
		<collision>
			<origin xyz="0 0 0"/>
			<geometry>
				<mesh filename="textured_objs/original-14.obj"/>
			</geometry>
		</collision>
		<collision>
			<origin xyz="0 0 0"/>
			<geometry>
				<mesh filename="textured_objs/original-27.obj"/>
			</geometry>
		</collision>
		<collision>
			<origin xyz="0 0 0"/>
			<geometry>
				<mesh filename="textured_objs/original-20.obj"/>
			</geometry>
		</collision>
		<collision>
			<origin xyz="0 0 0"/>
			<geometry>
				<mesh filename="textured_objs/original-19.obj"/>
			</geometry>
		</collision>
		<collision>
			<origin xyz="0 0 0"/>
			<geometry>
				<mesh filename="textured_objs/original-28.obj"/>
			</geometry>
		</collision>
		<collision>
			<origin xyz="0 0 0"/>
			<geometry>
				<mesh filename="textured_objs/original-21.obj"/>
			</geometry>
		</collision>
		<collision>
			<origin xyz="0 0 0"/>
			<geometry>
				<mesh filename="textured_objs/original-26.obj"/>
			</geometry>
		</collision>
		<collision>
			<origin xyz="0 0 0"/>
			<geometry>
				<mesh filename="textured_objs/original-2.obj"/>
			</geometry>
		</collision>
	</link>
	<joint name="joint_0" type="fixed">
		<origin rpy="1.570796326794897 0 -1.570796326794897" xyz="0 0 0"/>
		<child link="link_0"/>
		<parent link="base"/>
	</joint>
	<link name="link_1">
		<visual name="handle-49">
			<origin xyz="0 0 0"/>
			<geometry>
				<mesh filename="textured_objs/original-17.obj"/>
			</geometry>
		</visual>
		<visual name="drawer_front-59">
			<origin xyz="0 0 0"/>
			<geometry>
				<mesh filename="textured_objs/original-7.obj"/>
			</geometry>
		</visual>
		<visual name="drawer_front-59">
			<origin xyz="0 0 0"/>
			<geometry>
				<mesh filename="textured_objs/original-23.obj"/>
			</geometry>
		</visual>
		<visual name="drawer_front-59">
			<origin xyz="0 0 0"/>
			<geometry>
				<mesh filename="textured_objs/original-1.obj"/>
			</geometry>
		</visual>
		<visual name="drawer_side-60">
			<origin xyz="0 0 0"/>
			<geometry>
				<mesh filename="textured_objs/original-6.obj"/>
			</geometry>
		</visual>
		<visual name="drawer_side-61">
			<origin xyz="0 0 0"/>
			<geometry>
				<mesh filename="textured_objs/original-10.obj"/>
			</geometry>
		</visual>
		<visual name="drawer_back-62">
			<origin xyz="0 0 0"/>
			<geometry>
				<mesh filename="textured_objs/original-9.obj"/>
			</geometry>
		</visual>
		<visual name="drawer_back-62">
			<origin xyz="0 0 0"/>
			<geometry>
				<mesh filename="textured_objs/original-4.obj"/>
			</geometry>
		</visual>
		<visual name="drawer_bottom-63">
			<origin xyz="0 0 0"/>
			<geometry>
				<mesh filename="textured_objs/original-24.obj"/>
			</geometry>
		</visual>
		<visual name="drawer_bottom-63">
			<origin xyz="0 0 0"/>
			<geometry>
				<mesh filename="textured_objs/original-8.obj"/>
			</geometry>
		</visual>
		<collision>
			<origin xyz="0 0 0"/>
			<geometry>
				<mesh filename="textured_objs/original-17.obj"/>
			</geometry>
		</collision>
		<collision>
			<origin xyz="0 0 0"/>
			<geometry>
				<mesh filename="textured_objs/original-7.obj"/>
			</geometry>
		</collision>
		<collision>
			<origin xyz="0 0 0"/>
			<geometry>
				<mesh filename="textured_objs/original-23.obj"/>
			</geometry>
		</collision>
		<collision>
			<origin xyz="0 0 0"/>
			<geometry>
				<mesh filename="textured_objs/original-1.obj"/>
			</geometry>
		</collision>
		<collision>
			<origin xyz="0 0 0"/>
			<geometry>
				<mesh filename="textured_objs/original-6.obj"/>
			</geometry>
		</collision>
		<collision>
			<origin xyz="0 0 0"/>
			<geometry>
				<mesh filename="textured_objs/original-10.obj"/>
			</geometry>
		</collision>
		<collision>
			<origin xyz="0 0 0"/>
			<geometry>
				<mesh filename="textured_objs/original-9.obj"/>
			</geometry>
		</collision>
		<collision>
			<origin xyz="0 0 0"/>
			<geometry>
				<mesh filename="textured_objs/original-4.obj"/>
			</geometry>
		</collision>
		<collision>
			<origin xyz="0 0 0"/>
			<geometry>
				<mesh filename="textured_objs/original-24.obj"/>
			</geometry>
		</collision>
		<collision>
			<origin xyz="0 0 0"/>
			<geometry>
				<mesh filename="textured_objs/original-8.obj"/>
			</geometry>
		</collision>
	</link>
	<joint name="joint_1" type="prismatic">
		<origin xyz="0 0 0"/>
		<axis xyz="0 0 1"/>
		<child link="link_1"/>
		<parent link="link_0"/>
		<limit lower="0" upper="0.7120000000000002"/>
	</joint>
</robot>
