<robot name="partnet_83ab18386e87bf4efef598dabc93c115">
	<link name="base" />
	<link name="link_0">
		<collision>
			<origin xyz="-0.6071008788782839 -0.23394889741627845 -0.028473990602806643" />
			<geometry>
				<mesh filename="new_objs/101673_link_0_6.obj" />
			</geometry>
		</collision>
	<collision>
			<origin xyz="-0.6071008788782839 -0.23394889741627845 -0.028473990602806643" />
			<geometry>
				<mesh filename="new_objs/101673_link_0_11.obj" />
			</geometry>
		</collision>
	<collision>
			<origin xyz="-0.6071008788782839 -0.23394889741627845 -0.028473990602806643" />
			<geometry>
				<mesh filename="new_objs/101673_link_0_0.obj" />
			</geometry>
		</collision>
	<collision>
			<origin xyz="-0.6071008788782839 -0.23394889741627845 -0.028473990602806643" />
			<geometry>
				<mesh filename="new_objs/101673_link_0_10.obj" />
			</geometry>
		</collision>
	<collision>
			<origin xyz="-0.6071008788782839 -0.23394889741627845 -0.028473990602806643" />
			<geometry>
				<mesh filename="new_objs/101673_link_0_5.obj" />
			</geometry>
		</collision>
	<collision>
			<origin xyz="-0.6071008788782839 -0.23394889741627845 -0.028473990602806643" />
			<geometry>
				<mesh filename="new_objs/101673_link_0_4.obj" />
			</geometry>
		</collision>
	<collision>
			<origin xyz="-0.6071008788782839 -0.23394889741627845 -0.028473990602806643" />
			<geometry>
				<mesh filename="new_objs/101673_link_0_3.obj" />
			</geometry>
		</collision>
	<collision>
			<origin xyz="-0.6071008788782839 -0.23394889741627845 -0.028473990602806643" />
			<geometry>
				<mesh filename="new_objs/101673_link_0_12.obj" />
			</geometry>
		</collision>
	<collision>
			<origin xyz="-0.6071008788782839 -0.23394889741627845 -0.028473990602806643" />
			<geometry>
				<mesh filename="new_objs/101673_link_0_7.obj" />
			</geometry>
		</collision>
	<collision>
			<origin xyz="-0.6071008788782839 -0.23394889741627845 -0.028473990602806643" />
			<geometry>
				<mesh filename="new_objs/101673_link_0_2.obj" />
			</geometry>
		</collision>
	<collision>
			<origin xyz="-0.6071008788782839 -0.23394889741627845 -0.028473990602806643" />
			<geometry>
				<mesh filename="new_objs/101673_link_0_9.obj" />
			</geometry>
		</collision>
	<collision>
			<origin xyz="-0.6071008788782839 -0.23394889741627845 -0.028473990602806643" />
			<geometry>
				<mesh filename="new_objs/101673_link_0_8.obj" />
			</geometry>
		</collision>
	<collision>
			<origin xyz="-0.6071008788782839 -0.23394889741627845 -0.028473990602806643" />
			<geometry>
				<mesh filename="new_objs/101673_link_0_1.obj" />
			</geometry>
		</collision>
	<visual name="handle-part[&quot;id]">
			<origin xyz="-0.6071008788782839 -0.23394889741627845 -0.028473990602806643" />
			<geometry>
				<mesh filename="textured_objs/original-7.obj" />
			</geometry>
		</visual>
		</link>
	<joint name="joint_0" type="revolute">
		<origin xyz="0.6071008788782839 0.23394889741627845 0.028473990602806643" />
		<axis xyz="-1 0 0" />
		<child link="link_0" />
		<parent link="link_1" />
		<limit lower="-1.5707963267948966" upper="1.5707963267948966" />
	</joint>
	<link name="link_1">
		<collision>
			<origin xyz="0 0 0" />
			<geometry>
				<mesh filename="new_objs/101673_link_1_1.obj" />
			</geometry>
		</collision>
		<collision>
			<origin xyz="0 0 0" />
			<geometry>
				<mesh filename="new_objs/101673_link_1_0.obj" />
			</geometry>
		</collision>
		<visual name="base_body-part[&quot;id]">
			<origin xyz="0 0 0" />
			<geometry>
				<mesh filename="textured_objs/original-4.obj" />
			</geometry>
		</visual>
		<visual name="base_body-part[&quot;id]">
			<origin xyz="0 0 0" />
			<geometry>
				<mesh filename="textured_objs/original-3.obj" />
			</geometry>
		</visual>
		<visual name="base_body-part[&quot;id]">
			<origin xyz="0 0 0" />
			<geometry>
				<mesh filename="textured_objs/original-2.obj" />
			</geometry>
		</visual>
		<visual name="base_body-part[&quot;id]">
			<origin xyz="0 0 0" />
			<geometry>
				<mesh filename="textured_objs/original-8.obj" />
			</geometry>
		</visual>
		<visual name="base_body-part[&quot;id]">
			<origin xyz="0 0 0" />
			<geometry>
				<mesh filename="textured_objs/original-9.obj" />
			</geometry>
		</visual>
		<visual name="base_body-part[&quot;id]">
			<origin xyz="0 0 0" />
			<geometry>
				<mesh filename="textured_objs/original-5.obj" />
			</geometry>
		</visual>
		<visual name="base_body-part[&quot;id]">
			<origin xyz="0 0 0" />
			<geometry>
				<mesh filename="textured_objs/original-6.obj" />
			</geometry>
		</visual>
		<visual name="base_body-part[&quot;id]">
			<origin xyz="0 0 0" />
			<geometry>
				<mesh filename="textured_objs/original-11.obj" />
			</geometry>
		</visual>
		<visual name="base_body-part[&quot;id]">
			<origin xyz="0 0 0" />
			<geometry>
				<mesh filename="textured_objs/original-1.obj" />
			</geometry>
		</visual>
		<visual name="base_body-part[&quot;id]">
			<origin xyz="0 0 0" />
			<geometry>
				<mesh filename="textured_objs/original-10.obj" />
			</geometry>
		</visual>
		</link>
	<joint name="joint_1" type="fixed">
		<origin rpy="1.570796326794897 0 -1.570796326794897" xyz="0 0 0" />
		<child link="link_1" />
		<parent link="base" />
	</joint>
</robot>