<?xml version="1.0" ?>
<robot name="partnet_96325740-43a4-4d91-8301-8cac91428698">
	<link name="base"/>
	<link name="link_0">
		<visual name="handle-1">
			<origin xyz="-0.24199100000000007 -0.6190739312791156 0.008863188576718584"/>
			<geometry>
				<mesh filename="textured_objs/original-12.obj"/>
			</geometry>
		</visual>
		<collision>
			<origin xyz="-0.24199100000000007 -0.6190739312791156 0.008863188576718584"/>
			<geometry>
				<mesh filename="textured_objs/original-12.obj"/>
			</geometry>
		</collision>
	</link>
	<joint name="joint_0" type="fixed">
		<origin xyz="0.24199100000000007 0.6190739312791156 -0.008863188576718584"/>
		<axis xyz="-1 0 0"/>
		<child link="link_0"/>
		<parent link="link_4"/>
		<limit lower="-0.0" upper="3.141592653589793"/>
	</joint>
	<link name="link_1">
		<visual name="lock-2">
			<origin xyz="-0.5638830000000001 -0.6140162935418205 0.10098945949062198"/>
			<geometry>
				<mesh filename="textured_objs/original-4.obj"/>
			</geometry>
		</visual>
		<collision>
			<origin xyz="-0.5638830000000001 -0.6140162935418205 0.10098945949062198"/>
			<geometry>
				<mesh filename="textured_objs/original-4.obj"/>
			</geometry>
		</collision>
	</link>
	<joint name="joint_1" type="fixed">
		<origin xyz="0.5638830000000001 0.6140162935418205 -0.10098945949062198"/>
		<axis xyz="-1 0 0"/>
		<child link="link_1"/>
		<parent link="link_4"/>
		<limit lower="-0.0" upper="3.141592653589793"/>
	</joint>
	<link name="link_2">
		<visual name="lock-3">
			<origin xyz="-0.5638830000000001 -0.6140162935418205 0.10098945949062198"/>
			<geometry>
				<mesh filename="textured_objs/original-8.obj"/>
			</geometry>
		</visual>
		<collision>
			<origin xyz="-0.5638830000000001 -0.6140162935418205 0.10098945949062198"/>
			<geometry>
				<mesh filename="textured_objs/original-8.obj"/>
			</geometry>
		</collision>
	</link>
	<joint name="joint_2" type="fixed">
		<origin xyz="0.5638830000000001 0.6140162935418205 -0.10098945949062198"/>
		<axis xyz="-1 0 0"/>
		<child link="link_2"/>
		<parent link="link_4"/>
		<limit lower="-0.0" upper="3.141592653589793"/>
	</joint>
	<link name="link_3">
		<visual name="lid-4">
			<origin xyz="-0.5638830000000001 0.6355493775357086 -0.053726220875294516"/>
			<geometry>
				<mesh filename="textured_objs/original-10.obj"/>
			</geometry>
		</visual>
		<visual name="lid-4">
			<origin xyz="-0.5638830000000001 0.6355493775357086 -0.053726220875294516"/>
			<geometry>
				<mesh filename="textured_objs/original-9.obj"/>
			</geometry>
		</visual>
		<visual name="lid-4">
			<origin xyz="-0.5638830000000001 0.6355493775357086 -0.053726220875294516"/>
			<geometry>
				<mesh filename="textured_objs/original-3.obj"/>
			</geometry>
		</visual>
		<collision>
			<origin xyz="-0.5638830000000001 0.6355493775357086 -0.053726220875294516"/>
			<geometry>
				<mesh filename="textured_objs/original-10.obj"/>
			</geometry>
		</collision>
		<collision>
			<origin xyz="-0.5638830000000001 0.6355493775357086 -0.053726220875294516"/>
			<geometry>
				<mesh filename="textured_objs/original-9.obj"/>
			</geometry>
		</collision>
		<collision>
			<origin xyz="-0.5638830000000001 0.6355493775357086 -0.053726220875294516"/>
			<geometry>
				<mesh filename="textured_objs/original-3.obj"/>
			</geometry>
		</collision>
	</link>
	<joint name="joint_3" type="revolute">
		<origin xyz="0.5638830000000001 -0.6355493775357086 0.053726220875294516"/>
		<axis xyz="1 0 0"/>
		<child link="link_3"/>
		<parent link="link_4"/>
		<limit lower="0.0" upper="3.141592653589793"/>
	</joint>
	<link name="link_4">
		<visual name="base_body-5">
			<origin xyz="0 0 0"/>
			<geometry>
				<mesh filename="textured_objs/original-2.obj"/>
			</geometry>
		</visual>
		<visual name="base_body-5">
			<origin xyz="0 0 0"/>
			<geometry>
				<mesh filename="textured_objs/original-13.obj"/>
			</geometry>
		</visual>
		<visual name="base_body-5">
			<origin xyz="0 0 0"/>
			<geometry>
				<mesh filename="textured_objs/original-5.obj"/>
			</geometry>
		</visual>
		<visual name="base_body-5">
			<origin xyz="0 0 0"/>
			<geometry>
				<mesh filename="textured_objs/original-6.obj"/>
			</geometry>
		</visual>
		<visual name="base_body-5">
			<origin xyz="0 0 0"/>
			<geometry>
				<mesh filename="textured_objs/original-11.obj"/>
			</geometry>
		</visual>
		<visual name="base_body-5">
			<origin xyz="0 0 0"/>
			<geometry>
				<mesh filename="textured_objs/original-7.obj"/>
			</geometry>
		</visual>
		<visual name="base_body-5">
			<origin xyz="0 0 0"/>
			<geometry>
				<mesh filename="textured_objs/original-1.obj"/>
			</geometry>
		</visual>
		<visual name="base_body-5">
			<origin xyz="0 0 0"/>
			<geometry>
				<mesh filename="textured_objs/original-14.obj"/>
			</geometry>
		</visual>
		<collision>
			<origin xyz="0 0 0"/>
			<geometry>
				<mesh filename="textured_objs/original-2.obj"/>
			</geometry>
		</collision>
		<collision>
			<origin xyz="0 0 0"/>
			<geometry>
				<mesh filename="textured_objs/original-13.obj"/>
			</geometry>
		</collision>
		<collision>
			<origin xyz="0 0 0"/>
			<geometry>
				<mesh filename="textured_objs/original-5.obj"/>
			</geometry>
		</collision>
		<collision>
			<origin xyz="0 0 0"/>
			<geometry>
				<mesh filename="textured_objs/original-6.obj"/>
			</geometry>
		</collision>
		<collision>
			<origin xyz="0 0 0"/>
			<geometry>
				<mesh filename="textured_objs/original-11.obj"/>
			</geometry>
		</collision>
		<collision>
			<origin xyz="0 0 0"/>
			<geometry>
				<mesh filename="textured_objs/original-7.obj"/>
			</geometry>
		</collision>
		<collision>
			<origin xyz="0 0 0"/>
			<geometry>
				<mesh filename="textured_objs/original-1.obj"/>
			</geometry>
		</collision>
		<collision>
			<origin xyz="0 0 0"/>
			<geometry>
				<mesh filename="textured_objs/original-14.obj"/>
			</geometry>
		</collision>
	</link>
	<joint name="joint_4" type="fixed">
		<origin rpy="1.570796326794897 0 -1.570796326794897" xyz="0 0 0"/>
		<child link="link_4"/>
		<parent link="base"/>
	</joint>
</robot>
