<?xml version="1.0" ?>
<robot name="partnet_67f98b83c3ede0ac41b275920fc7b6f">
	<link name="base"/>
	<link name="link_0">
		<visual name="handle-1">
			<origin xyz="-0.0020023565397967007 -0.4673673194432551 0.008406455440508418"/>
			<geometry>
				<mesh filename="textured_objs/original-4.obj"/>
			</geometry>
		</visual>
		<visual name="handle-1">
			<origin xyz="-0.0020023565397967007 -0.4673673194432551 0.008406455440508418"/>
			<geometry>
				<mesh filename="textured_objs/original-6.obj"/>
			</geometry>
		</visual>
		<visual name="handle-1">
			<origin xyz="-0.0020023565397967007 -0.4673673194432551 0.008406455440508418"/>
			<geometry>
				<mesh filename="textured_objs/original-2.obj"/>
			</geometry>
		</visual>
		<visual name="handle-1">
			<origin xyz="-0.0020023565397967007 -0.4673673194432551 0.008406455440508418"/>
			<geometry>
				<mesh filename="textured_objs/original-5.obj"/>
			</geometry>
		</visual>
		<visual name="handle-1">
			<origin xyz="-0.0020023565397967007 -0.4673673194432551 0.008406455440508418"/>
			<geometry>
				<mesh filename="textured_objs/original-3.obj"/>
			</geometry>
		</visual>
		<collision>
			<origin xyz="-0.0020023565397967007 -0.4673673194432551 0.008406455440508418"/>
			<geometry>
				<mesh filename="textured_objs/original-4.obj"/>
			</geometry>
		</collision>
		<collision>
			<origin xyz="-0.0020023565397967007 -0.4673673194432551 0.008406455440508418"/>
			<geometry>
				<mesh filename="textured_objs/original-6.obj"/>
			</geometry>
		</collision>
		<collision>
			<origin xyz="-0.0020023565397967007 -0.4673673194432551 0.008406455440508418"/>
			<geometry>
				<mesh filename="textured_objs/original-2.obj"/>
			</geometry>
		</collision>
		<collision>
			<origin xyz="-0.0020023565397967007 -0.4673673194432551 0.008406455440508418"/>
			<geometry>
				<mesh filename="textured_objs/original-5.obj"/>
			</geometry>
		</collision>
		<collision>
			<origin xyz="-0.0020023565397967007 -0.4673673194432551 0.008406455440508418"/>
			<geometry>
				<mesh filename="textured_objs/original-3.obj"/>
			</geometry>
		</collision>
	</link>
	<joint name="joint_0" type="revolute">
		<origin xyz="0.0020023565397967007 0.4673673194432551 -0.008406455440508418"/>
		<axis xyz="1 0 0.07"/>
		<child link="link_0"/>
		<parent link="link_1"/>
		<limit lower="-2.236813969355932" upper="1.9666370011472105"/>
	</joint>
	<link name="link_1">
		<visual name="base_body-2">
			<origin xyz="0 0 0"/>
			<geometry>
				<mesh filename="textured_objs/original-1.obj"/>
			</geometry>
		</visual>
		<collision>
			<origin xyz="0 0 0"/>
			<geometry>
				<mesh filename="textured_objs/original-1.obj"/>
			</geometry>
		</collision>
	</link>
	<joint name="joint_1" type="fixed">
		<origin rpy="1.570796326794897 0 -1.570796326794897" xyz="0 0 0"/>
		<child link="link_1"/>
		<parent link="base"/>
	</joint>
</robot>
